<?xml version="1.0"?>
<robot name="ugv_apriltags">

	<!-- Dummy link -->
	<!-- <link name="dummy">
	</link> -->

	<link name="ugv_link">
		<visual>
			<geometry>
				<box size="0.6 0.4 0.3"/>
			</geometry>
			<!-- <material name="Gazebo/Grey">
				<color rgba="0.937 0.161 0.161 1"/>
			</material> -->
		</visual>
		<collision>
			<geometry>
				<box size="0.6 0.4 0.3"/>
			</geometry>
		</collision>
		<inertial>
			<mass value="5.0"/>
			<inertia ixx="0.93854167" iyy="0.93854167" izz="1.87500"
							ixy="0.0" ixz="0.0" iyz="0.0"/>
		</inertial>
	</link>
	<!-- <joint name="dummy_joint" type="fixed">
		<axis xyz="0 0 1"/>
		<parent link="dummy"/>
		<child link="ugv_link"/>
		<origin rpy="0 0 0" xyz="0 0 0"/>
	</joint> -->

	<link name="front_left_wheel">
		<visual>
			<geometry>
				<cylinder length="0.05" radius="0.1"/>
			</geometry>
			<material name="black">
				<color rgba="0 0 0 1"/>
			</material>
		</visual>
		<collision>
			<geometry>
				<cylinder length="0.05" radius="0.1"/>
			</geometry>
			<contact_coefficients>
				<mu>0.5</mu>
			</contact_coefficients>
		</collision>
		<inertial>
			<mass value="1.0"/>
			<inertia ixx="0.00110833" iyy="0.00110833" izz="0.0018"
				ixy="0.0" ixz="0.0" iyz="0.0"/>
		</inertial>
	</link>
	<joint name="front_left_wheel_joint" type="continuous">
		<axis xyz="0 0 1"/>
		<parent link="ugv_link"/>
		<child link="front_left_wheel"/>
		<origin rpy="-1.5708 0 0" xyz="0.179671 0.2 -0.087435"/>
	</joint>
	
	<link name="front_right_wheel">
		<visual>
			<geometry>
				<cylinder length="0.05" radius="0.1"/>
			</geometry>
			<material name="black">
				<color rgba="0 0 0 1"/>
			</material>
		</visual>
		<collision>
			<geometry>
				<cylinder length="0.05" radius="0.1"/>
			</geometry>
			<contact_coefficients>
				<mu>0.5</mu>
			</contact_coefficients>
		</collision>
		<inertial>
			<mass value="1.0"/>
			<inertia ixx="0.00110833" iyy="0.00110833" izz="0.0018"
				ixy="0.0" ixz="0.0" iyz="0.0"/>
		</inertial>
	</link>
	<joint name="front_right_wheel_joint" type="continuous">
		<axis xyz="0 0 1"/>
		<parent link="ugv_link"/>
		<child link="front_right_wheel"/>
		<origin rpy="-1.5708 0 0" xyz="0.179671 -0.2 -0.087435"/>
	</joint>
	
	<link name="rear_left_wheel">
		<visual>
			<geometry>
				<cylinder length="0.05" radius="0.1"/>
			</geometry>
			<material name="black">
				<color rgba="0 0 0 1"/>
			</material>
		</visual>
		<collision>
			<geometry>
				<cylinder length="0.05" radius="0.1"/>
			</geometry>
		</collision>
		<inertial>
			<mass value="1.0"/>
			<inertia ixx="0.00110833" iyy="0.00110833" izz="0.0018"
				ixy="0.0" ixz="0.0" iyz="0.0"/>
		</inertial>
	</link>
	<joint name="rear_left_wheel_joint" type="continuous">
		<axis xyz="0 0 1"/>
		<parent link="ugv_link"/>
		<child link="rear_left_wheel"/>
		<origin rpy="-1.5708 0 0" xyz="-0.179671 0.2 -0.087435"/>
	</joint>
	
	<link name="rear_right_wheel">
		<visual>
			<geometry>
				<cylinder length="0.05" radius="0.1"/>
			</geometry>
			<material name="black">
				<color rgba="0 0 0 1"/>
			</material>
		</visual>
		<collision>
			<geometry>
				<cylinder length="0.05" radius="0.1"/>
			</geometry>
		</collision>
		<inertial>
			<mass value="1.0"/>
			<inertia ixx="0.00110833" iyy="0.00110833" izz="0.0018"
				ixy="0.0" ixz="0.0" iyz="0.0"/>
		</inertial>
	</link>
	<joint name="rear_right_wheel_joint" type="continuous">
		<axis xyz="0 0 1"/>
		<parent link="ugv_link"/>
		<child link="rear_right_wheel"/>
		<origin rpy="-1.5708 0 0" xyz="-0.179671 -0.2 -0.087435"/>
	</joint>
	

	<link name="plate_link">
		<visual>
			<geometry>
				<box size="1.5 1.5 0.05"/>
			</geometry>
			<material name="green">
				<color rgba="0.161 0.8 0.161 1"/>
			</material>
		</visual>
		<collision>
			<geometry>
				<box size="1.5 1.5 0.03"/>
			</geometry>
		</collision>
		<inertial>
			<mass value="3.0"/>
			<inertia ixx="0.563125" iyy="0.563125" izz="1.125"
							ixy="0.0" ixz="0.0" iyz="0.0"/>
		</inertial>
	</link>
	<joint name="plate_joint" type="fixed">
		<parent link="ugv_link"/>
		<child link="plate_link"/>
		<origin rpy="0 0 0" xyz="0 0 0.15"/>
	</joint>

	<!-- AprilTags -->
	<link name="apriltag_link1">
		<visual>
			<geometry>
				<box size='0.30 0.30 0.005' rpy="0 0 0"/>
			</geometry>
		</visual>
		<collision>
			<origin xyz="0 0 0.0" rpy="0 0 0" />
			<geometry>
				<box size="0.30 0.30 0.005" rpy="0 0 0" />
			</geometry>
		</collision>
	</link>
	<joint name="apriltag_link_joint1" type="fixed">
		<parent link="plate_link"/>
		<child link="apriltag_link1"/>
		<origin rpy="0 0 1.5708" xyz="0 0 0.03"/>
	</joint>
	<gazebo reference="apriltag_link1">
		<material>Apriltag36_11_00002</material>
	</gazebo>

	<link name="apriltag_link2">
		<visual>
			<geometry>
				<box size='0.125 0.125 0.005' rpy="0 0 0"/>
			</geometry>
		</visual>
		<collision>
			<origin xyz="0 0 0.0" rpy="0 0 0" />
			<geometry>
				<box size="0.125 0.125 0.005" rpy="0 0 0" />
			</geometry>
		</collision>
	</link>
	<joint name="apriltag_link_joint2" type="fixed">
		<parent link="plate_link"/>
		<child link="apriltag_link2"/>
		<origin rpy="0 0 1.5708" xyz="0.25 0 0.03"/>
	</joint>
	<gazebo reference="apriltag_link2">
		<material>Apriltag36_11_00004</material>
	</gazebo>

	<link name="fractal_marker_link">
		<visual>
		<geometry>
			<box size='0.30 0.30 0.005' rpy="0 0 0"/>
		</geometry>

		</visual>
		<collision>
		<origin xyz="0 0 0.0" rpy="0 0 0" />
		<geometry>
			<box size="0.30 0.30 0.005" rpy="0 0 0" />
		</geometry>
		</collision>
		<inertial>
		<mass value="0.1"/>
		<inertia ixx="0.0001" iyy="0.0001" izz="0.0001"
				ixy="0.0" ixz="0.0" iyz="0.0"/>
		</inertial>
	</link>
	<joint name="fractal_marker_joint" type="fixed">
		<parent link="plate_link"/>
		<child link="fractal_marker_link"/>
		<origin rpy="0 0 1.5708" xyz="0.5 0 0.03"/>
	</joint>
	<gazebo reference="fractal_marker_link">
		<material>FRACTAL_4L_6</material>
	</gazebo>

	<!-- Plugins -->
	<gazebo>
		<plugin name="differential_drive_controller" filename="libgazebo_ros_diff_drive.so">
			<leftJoint>front_left_wheel_joint</leftJoint>
			<rightJoint>front_right_wheel_joint</rightJoint>
			<robotBaseFrame>ugv_link</robotBaseFrame>
			<wheelSeparation>0.4</wheelSeparation>
			<wheelDiameter>0.2</wheelDiameter>
			<publishWheelJointState>true</publishWheelJointState>
		</plugin>
	</gazebo>
	
	<gazebo>
		<plugin name="joint_state_publisher" filename="libgazebo_ros_joint_state_publisher.so">
			<jointName>rear_left_wheel_joint, rear_right_wheel_joint</jointName>
		</plugin>
	</gazebo>


</robot>

